File: GUI/Example/D18 full spectra.vms
VAMAS Surface Chemical Analysis Standard Data Transfer Format 1988 May 4


ScientaOmicron

6
Created with: MATRIX V3.2.3-release_v1616-tags/release/MatrixKit_3.2.3/Main-193736
Date of Acquisition: 2021.08.31
CREATION COMMENT START

CREATION COMMENT END
SourceAnalyserAngle: 0 d
NORM
REGULAR
1
0
0
0
0
0
1
survey

2024
10
30
23
37
36
3
5
Sample Position X: 0 micro m
Sample Position Y: 0 micro m
Sample Position Z: 0 micro m
Aperture: 2
Exit Slit: 3 x 10 mm
UPS
He I a 21.2 eV
21.2
1e+037
1e+037
1e+037
0
0
FAT
5
1e+037
4.5
1e+037
1e+037
1e+037
1e+037
1e+037
survey

0
Kinetic Energy
eV
12
0.05
2
Intensity
d
Transmission
d
pulse counting
0.5
1
0
90
270
1e+037
0
842
0
6385.46
5
5
3.82
5
2.6
5
5.26
5
6.2
5
4.38
5
2.24
5
2.08
5
6.08
5
1.5
5
3.54
5
4.54
5
1.92
5
2.98
5
1.06
5
3.9
5
1.44
5
3.46
5
5.76
5
4.56
5
7.6
5
5.32
5
5.32
5
5.58
5
5.86
5
5.76
5
3.66
5
2.16
5
3.82
5
5.8
5
4.9
5
4.2
5
9.4
5
7.74
5
4.18
5
6.68
5
5
5
11.06
5
13.16
5
12.54
5
11.14
5
7.6
5
14.66
5
12.66
5
21.68
5
22.74
5
20.02
5
15.52
5
38.92
5
42.98
5
465.38
5
2852.94
5
4827.1
5
5794.16
5
6269.74
5
6385.46
5
6071.3
5
5920.14
5
5619.2
5
5471.1
5
5224.56
5
4960.56
5
4755.28
5
4548.44
5
4500.32
5
4153.3
5
4150.5
5
4017.1
5
3922.9
5
3909.7
5
3737.84
5
3663.26
5
3611.14
5
3468.7
5
3339.84
5
3343.88
5
3168.68
5
3060.04
5
2923.82
5
2917.84
5
2781
5
2641.74
5
2565.72
5
2418.34
5
2316.3
5
2199.12
5
2148.24
5
2075.26
5
1927.88
5
1877.7
5
1834.68
5
1788.18
5
1660.7
5
1626.48
5
1586.62
5
1470.9
5
1469.2
5
1401.12
5
1351.3
5
1308.2
5
1237.9
5
1195.6
5
1184.54
5
1150.42
5
1161.56
5
1069.9
5
1029.36
5
1117.34
5
1049.06
5
1040.52
5
962.82
5
941.54
5
966.2
5
937.24
5
930.1
5
872.54
5
913.46
5
852.52
5
836.16
5
786.66
5
858.78
5
798.02
5
795.96
5
768.18
5
770.06
5
740.02
5
732.46
5
691.7
5
668.62
5
674.02
5
642.38
5
621.08
5
689.96
5
597.1
5
579.6
5
577.86
5
593.56
5
582.68
5
570.3
5
501.84
5
520.32
5
530.94
5
484.34
5
489.62
5
477
5
480.56
5
469.42
5
460.78
5
425.7
5
448.94
5
421.1
5
413.36
5
430.5
5
430.32
5
397.88
5
399.84
5
421.84
5
392.58
5
386.38
5
398.76
5
430.66
5
408.96
5
408.34
5
363.38
5
420.82
5
407.4
5
406.34
5
396.7
5
396.58
5
383.5
5
424.62
5
428.1
5
423.84
5
399.06
5
402.62
5
408.5
5
425.9
5
406.84
5
410.7
5
381.52
5
398.58
5
409.3
5
379.22
5
383.08
5
397.7
5
389.8
5
392.46
5
395.46
5
403.2
5
416.1
5
395.62
5
416.92
5
412.18
5
389.42
5
437.52
5
433.4
5
425.06
5
418.2
5
401.38
5
436.38
5
394.76
5
419.36
5
436.04
5
425.6
5
412.44
5
394.84
5
399.26
5
386.42
5
376.06
5
423.16
5
398.84
5
418.26
5
414.06
5
379.98
5
364.86
5
390.9
5
399.64
5
416.86
5
381.76
5
384.58
5
397.76
5
425.88
5
407.6
5
418.16
5
442.14
5
410.88
5
426.12
5
423.1
5
431.94
5
418.42
5
435.84
5
442.12
5
422.68
5
387.6
5
459.26
5
411.88
5
407.34
5
426.44
5
407.28
5
445.98
5
443.74
5
442.18
5
459.9
5
483.8
5
445.36
5
437.44
5
433.48
5
442.14
5
455.38
5
453.12
5
440.1
5
432.42
5
445.42
5
438.22
5
451.02
5
435.12
5
403.28
5
433.48
5
438.98
5
439.22
5
421.34
5
426.34
5
424.9
5
413.14
5
428.7
5
412.56
5
390.54
5
417.38
5
384.38
5
386
5
348.46
5
341.94
5
363.96
5
363.12
5
349.2
5
324.68
5
341.42
5
313.32
5
323.68
5
315.02
5
309.88
5
310.72
5
299.32
5
277.18
5
277.94
5
259.96
5
232.06
5
219.88
5
219.66
5
198.7
5
191.04
5
188.3
5
184.28
5
165.36
5
143.96
5
131.52
5
122.42
5
108.84
5
89.8
5
75.92
5
59.4
5
44.12
5
48.24
5
39.36
5
33.86
5
30.8
5
37.72
5
38.04
5
30.4
5
41.4
5
46.6
5
43.86
5
46.86
5
45.72
5
66.14
5
50.68
5
51.64
5
46.4
5
57.24
5
57.86
5
62.92
5
50.22
5
55.4
5
52.04
5
58.1
5
62.22
5
42.92
5
44.22
5
45.26
5
51.84
5
48.18
5
31.28
5
29.3
5
30.08
5
21.86
5
18.2
5
16.9
5
18.7
5
6.28
5
18.58
5
12.02
5
12.34
5
8.24
5
12.46
5
8.28
5
10.02
5
13.44
5
10.76
5
8.58
5
11.36
5
14.48
5
11.86
5
10.14
5
13.14
5
12.12
5
15.88
5
12.58
5
7.1
5
6.76
5
7.14
5
6.18
5
10.16
5
8.94
5
11.1
5
8.88
5
5.54
5
3.94
5
6.84
5
4.28
5
3.18
5
2.68
5
2.64
5
1.36
5
1.64
5
0
5
0
5
0
5
0
5
0
5
0.78
5
1.26
5
0.96
5
0
5
0
5
0
5
0
5
0
5
0
5
5.68434e-014
5
1
5
0
5
1.32
5
1.56
5
1.04
5
1.08
5
0.54
5
0.46
5
0
5
0.78
5
0.22
5
0
5
0
5
1
5
5.68434e-014
5
0
5
0
5
0
5
0
5
0
5
0
5
0
5
0
5
0
5
0
5
0
5
0
5
0
5
0
5
0
5
0
5
0
5
0
5
end of experiment